<?xml version="1.0"?>

<robot xmlns:xacro="http://www.ros.org/wiki/xacro" name="scorbot_model">

    <xacro:macro name="defaultInertial" params="mass">
        <inertial>
            <mass value="${mass}" />
            <inertia ixx="1.0" ixy="0.0" ixz="0.0" iyy="1.0" iyz="0.0" izz="1.0" />
        </inertial>
    </xacro:macro>

    <link name="world" />

    <link name="base_Link">
        <xacro:defaultInertial mass="1" />

        <visual>
            <origin xyz="0 0 0" rpy="0 0 0" />
            <geometry>
                <mesh filename="package://sac_description/meshes/base_Link.STL" />
      </geometry>
      <material name="">
        <color rgba="0.01706 0.01961 0.02824 1" />
      </material>
    </visual>
    <collision>
      <origin xyz="0 0 0" rpy="0 0 0" />
      <geometry>
        <mesh filename="package://sac_description/meshes/base_Link.STL" />
      </geometry>
    </collision>
  </link>
  
  <joint name="world_joint" type="fixed">
    <parent link="world" />
    <child link="base_Link" />
  </joint>


  <link name="shoulder_Link">
        <xacro:defaultInertial mass="1" />

    <visual>
      <origin xyz="0 0 0" rpy="0 0 0" />
      <geometry>
        <mesh filename="package://sac_description/meshes/shoulder_Link.STL" />
      </geometry>
      <material name="">
        <color rgba="0.02941 0.04902 0.24902 1" />
      </material>
    </visual>
    <collision>
      <origin xyz="0 0 0" rpy="0 0 0" />
      <geometry>
        <mesh filename="package://sac_description/meshes/shoulder_Link.STL" />
      </geometry>
    </collision>
  </link>

  <joint name="base_joint" type="revolute">
    <origin xyz="0.13222 -0.16175 0.21721" rpy="0.063114 2.647E-17 -0.063535" />
    <parent link="base_Link" />
    <child link="shoulder_Link" />
    <axis xyz="0 0 1" />
    <limit lower="-2.7054" upper="2.7054" effort="5" velocity="0.3488" />
  </joint>

  <transmission name="baseTransmission">
    <type>transmission_interface/SimpleTransmission</type>
    <joint name="base_joint" type="SimpleTransmission">
      <hardwareInterface>EffortJointInterface</hardwareInterface>
    </joint>
    <actuator name="base_motor">
      <machanicalReduction>1</machanicalReduction>
      <hardwareInterface>EffortJointInterface</hardwareInterface>
    </actuator>
  </transmission>

  <link name="elbow_Link">
        <xacro:defaultInertial mass="1" />

    <visual>
      <origin xyz="0 0 0" rpy="0 0 0" />
      <geometry>
        <mesh filename="package://sac_description/meshes/elbow_Link.STL" />
      </geometry>
      <material name="">
        <color rgba="0.02941 0.04902 0.34902 1" />
      </material>
    </visual>
    <collision>
      <origin xyz="0 0 0" rpy="0 0 0" />
      <geometry>
        <mesh filename="package://sac_description/meshes/elbow_Link.STL" />
      </geometry>
    </collision>
  </link>

  <joint name="shoulder_joint" type="revolute">
    <origin xyz="0 -0.029 0.19766" rpy="0 0 0" />
    <parent link="shoulder_Link" />
    <child link="elbow_Link" />
    <axis xyz="-1 0 0" />
    <limit lower="-0.6109" upper="2.2689" effort="100" velocity="0.4587" />
  </joint>

  <transmission name="shoulderTransmission">
    <type>transmission_interface/SimpleTransmission</type>
    <joint name="shoulder_joint" type="SimpleTransmission">
      <hardwareInterface>EffortJointInterface</hardwareInterface>
    </joint>
    <actuator name="shoulder_motor">
      <machanicalReduction>1</machanicalReduction>
      <hardwareInterface>EffortJointInterface</hardwareInterface>
    </actuator>
  </transmission>

  <link name="pitch_Link">
        <xacro:defaultInertial mass="1" />

    <visual>
      <origin xyz="0 0 0" rpy="0 0 0" />
      <geometry>
        <mesh filename="package://sac_description/meshes/pitch_Link.STL" />
      </geometry>
      <material name="">
        <color rgba="0.02941 0.04902 0.44902 1" />
      </material>
    </visual>
    <collision>
      <origin xyz="0 0 0" rpy="0 0 0" />
      <geometry>
        <mesh filename="package://sac_description/meshes/pitch_Link.STL" />
      </geometry>
    </collision>
  </link>
  
  <joint name="elbow_joint" type="revolute">
    <origin xyz="0 -0.22 0" rpy="1.3878E-17 1.6914E-16 1.3461E-15" />
    <parent link="elbow_Link" />
    <child link="pitch_Link" />
    <axis xyz="1 0 0" />
    <limit lower="-2.2689" upper="2.2689" effort="25" velocity="0.4587" />
  </joint>

  <transmission name="elbowTransmission">
    <type>transmission_interface/SimpleTransmission</type>
    <joint name="elbow_joint" type="SimpleTransmission">
      <hardwareInterface>EffortJointInterface</hardwareInterface>
    </joint>
    <actuator name="elbow_motor">
      <machanicalReduction>1</machanicalReduction>
      <hardwareInterface>EffortJointInterface</hardwareInterface>
    </actuator>
  </transmission>

  <link name="roll_Link">
        <xacro:defaultInertial mass="1" />

    <visual>
      <origin xyz="0 0 0" rpy="0 0 0" />
      <geometry>
        <mesh filename="package://sac_description/meshes/roll_Link.STL" />
      </geometry>
      <material name="">
        <color rgba="0.02941 0.14902 0.14902 1" />
      </material>
    </visual>
    <collision>
      <origin xyz="0 0 0" rpy="0 0 0" />
      <geometry>
        <mesh filename="package://sac_description/meshes/roll_Link.STL" />
      </geometry>
    </collision>
  </link>
  
  <joint name="pitch_joint" type="revolute">
    <origin xyz="0 -0.22 0" rpy="-1.5708 -1.5708 0" />
    <parent link="pitch_Link" />
    <child link="roll_Link" />
    <axis xyz="0 1 0" />
    <limit lower="-2.2689" upper="2.2689" effort="2" velocity="1.4478" />
  </joint>

  <transmission name="pitchTransmission">
    <type>transmission_interface/SimpleTransmission</type>
    <joint name="pitch_joint" type="SimpleTransmission">
      <hardwareInterface>EffortJointInterface</hardwareInterface>
    </joint>
    <actuator name="pitch_motor">
      <machanicalReduction>1</machanicalReduction>
      <hardwareInterface>EffortJointInterface</hardwareInterface>
    </actuator>
  </transmission>

  <link name="gripper_Link">
        <xacro:defaultInertial mass="1" />

    <visual>
      <origin xyz="0 0 0" rpy="0 0 0" />
      <geometry>
        <mesh filename="package://sac_description/meshes/gripper_Link.STL" />
      </geometry>
      <material name="">
        <color rgba="0.1 0.1 0.1 1" />
      </material>
    </visual>
    <collision>
      <origin xyz="0 0 0" rpy="0 0 0" />
      <geometry>
        <mesh filename="package://sac_description/meshes/gripper_Link.STL" />
      </geometry>
    </collision>
  </link>

  <joint name="roll_joint" type="revolute">
    <origin xyz="0 0 0.01" rpy="0 0 0" />
    <parent link="roll_Link" />
    <child link="gripper_Link" />
    <axis xyz="0 0 1" />
    <limit lower="-1000" upper="1000" effort="4" velocity="1.8491" />
  </joint>

  <transmission name="rollTransmission">
    <type>transmission_interface/SimpleTransmission</type>
    <joint name="roll_joint" type="SimpleTransmission">
      <hardwareInterface>EffortJointInterface</hardwareInterface>
    </joint>
    <actuator name="roll_motor">
      <machanicalReduction>1</machanicalReduction>
      <hardwareInterface>EffortJointInterface</hardwareInterface>
    </actuator>
  </transmission>

    <link name="pad1_Link">
        <xacro:defaultInertial mass="1" />

        <visual>
            <geometry>
                <box size="0.07 0.01 0.01" />
            </geometry>
            <origin xyz="-0.035 0 0" rpy="0 0 0" />
            <material name="">
                <color rgba="0.1 0 0 1" />
            </material>    
        </visual>
        <collision>
            <origin xyz="-0.035 0 0" rpy="0 0 0" />
            <geometry>
                <box size="0.07 0.01 0.01" />
            </geometry>
            <material name="">
                <color rgba="0.1 0 0 1" />
            </material>
        </collision>
    </link>

  <joint name="pad1_joint" type="revolute">
    <origin xyz="0 -0.0545 -0.0905" rpy="1.5708 -0.74758 -1.5708" />
    <parent link="gripper_Link" />
    <child link="pad1_Link" />
    <axis xyz="0 0 1" />
    <limit lower="0" upper="1.5709" effort="1" velocity="2" />
  </joint>

  <transmission name="pad1Transmission">
    <type>transmission_interface/SimpleTransmission</type>
    <joint name="pad1_joint" type="SimpleTransmission">
      <hardwareInterface>EffortJointInterface</hardwareInterface>
    </joint>
    <actuator name="pad1_motor">
      <machanicalReduction>1</machanicalReduction>
      <hardwareInterface>EffortJointInterface</hardwareInterface>
    </actuator>
  </transmission>

    <link name="pad2_Link">
        <xacro:defaultInertial mass="1" />

        <visual>
            <geometry>
                <box size="0.07 0.01 0.01" />
            </geometry>
            <origin xyz="-0.035 0 0" rpy="0 0 0" />
            <material name="">
                <color rgba="0.1 0 0 1" />
            </material>    
        </visual>
        <collision>
            <geometry>
                <box size="0.07 0.01 0.01" />
            </geometry>
            <origin xyz="-0.035 0 0" rpy="0 0 0" />
            <material name="">
                <color rgba="0.1 0 0 1" />
            </material>
        </collision>
    </link>

  <joint name="pad2_joint" type="revolute">
    <origin xyz="0 0.0545 -0.0905" rpy="-1.5708 -0.74758 1.5708" />
    <parent link="gripper_Link" />
    <child link="pad2_Link" />
    <axis xyz="0 0 -1" />
    <limit lower="0" upper="1.5709" effort="1" velocity="2" />
  </joint>

  <transmission name="pad2Transmission">
    <type>transmission_interface/SimpleTransmission</type>
    <joint name="pad2_joint" type="SimpleTransmission">
      <hardwareInterface>EffortJointInterface</hardwareInterface>
    </joint>
    <actuator name="pad2_motor">
      <machanicalReduction>1</machanicalReduction>
      <hardwareInterface>EffortJointInterface</hardwareInterface>
    </actuator>
  </transmission>


    <!-- Gazebo plugin for ROS Control -->
    <gazebo>
        <plugin name="gazebo_ros_control" filename="libgazebo_ros_control.so">
            <robotNamespace>/scorbot</robotNamespace>
        </plugin>
    </gazebo>
</robot>
